<?xml version="1.0" encoding="UTF-8"?>
<!-- Generated by org.testng.reporters.JUnitXMLReporter -->
<testsuite hostname="LXG-PC" name="127.0.0.1:62001" tests="1" failures="1" timestamp="14 Aug 2016 08:56:20 GMT" time="45.985" errors="0">
  <testcase name="testTestSuite" time="33.211" classname="cn.crazy.appium.keyworddriver.TestSuiteByExcel">
    <failure type="java.lang.AssertionError" message="执行出现异常，测试用例执行失败！">
      <![CDATA[java.lang.AssertionError: 执行出现异常，测试用例执行失败！
	at cn.crazy.appium.keyworddriver.TestSuiteByExcel.testTestSuite(TestSuiteByExcel.java:88)
	at java.util.concurrent.FutureTask.run(FutureTask.java:266)
	at java.util.concurrent.ThreadPoolExecutor.runWorker(ThreadPoolExecutor.java:1142)
	at java.util.concurrent.ThreadPoolExecutor$Worker.run(ThreadPoolExecutor.java:617)
	at java.lang.Thread.run(Thread.java:745)
... Removed 17 stack frames]]>
    </failure>
  </testcase> <!-- testTestSuite -->
</testsuite> <!-- 127.0.0.1:62001 -->
